<?xml version="1.0"?>
<robot name="cylinder">
     <!-- Base link -->
    <link name="hand_root">
        <origin xyz="0 0 0"/>
    </link>
    <joint name="root_to_base" type="fixed">
        <parent link="hand_root"/>
        <child link="palm_link"/>
        <origin xyz="0 0 0.095"/>
    </joint>
    <link name="palm_link">
        <visual>
        <geometry>
            <mesh filename="package://allegro_hand_description/meshes/base_link.STL"/>
        </geometry>
        <origin rpy="0 0 0" xyz="0 0 0 "/>
        <material name="black">
            <color rgba="0.2 0.2 0.2 1"/>
        </material>
        </visual>
        <collision>
        <origin rpy="0 0 0" xyz="-0.009300 0 -0.0475"/>
        <geometry>
            <box size="0.0408 0.1130 0.095"/>
        </geometry>
        </collision>
    </link>
    <link name="object_link">
        <visual>
            <geometry>
                <box size="0.0196 0.0275 0.0164"/>
            </geometry>
            <origin rpy="0 0 0" xyz="0.1 0 0 "/>
            <material name="black">
                <color rgba="0.5 0.2 0.2 0.5"/>
            </material>
        </visual>
    </link>
    <joint name="object_joint" type="revolute">
        <axis xyz="0 0 1"/>
        <limit effort="15" lower="-0.47" upper="0.47" velocity="7"/>
        <parent link="hand_root"/>
        <child link="object_link"/>
        <origin rpy="0 0 0" xyz="0 0.0435 -0.001542"/>
        <dynamics damping="3" friction="10"/>
    </joint>
</robot>